Workbook

Sheet Start here
A1: GCSE study plan – aiming for top grades
A2: Built 14 Oct 2026. Yellow cells are yours to edit; everything else updates from them.
A4: The rules that make revision stick
A5: 1. Test, don't reread | B5: Every session should make you pull answers out of your head (flashcards, blurting, questions, papers). Rereading and highlighting feel productive but are among the least effective techniques (Dunlosky et al., 2013, "Improving Students' Learning With Effective Learning Techniques", Psychological Science in the Public Interest).
A6: 2. Space it out | B6: Little and often beats cramming. The app's flashcards (FSRS) schedule reviews just before you'd forget – do your due cards every day, including weekends.
A7: 3. Mix it up (interleave) | B7: Once a topic is learnt, practise it mixed with others (mixed question sets, full papers). It feels harder but transfers better to the exam.
A8: 4. Practise the exam itself | B8: Knowledge gets you most marks; exam technique gets the last 10–20%. Do timed questions and papers, mark them strictly with the mark scheme, and learn the wording examiners reward.
A9: 5. Close the loop on mistakes | B9: Every mark you drop goes into the app's Past papers → mistakes log, then becomes a flashcard. The same mistake should never cost you twice.
A10: 6. Sleep and breaks | B10: 40-minute sessions with short breaks; 8–9 hours' sleep consolidates memory. Late-night cramming costs more than it gains.
A12: How to use this workbook
A13: November tests | B13: START HERE NOW: your day-by-day plan for the early-November Biology and English Language tests, a Biology topic tracker that puts your weakest tested topics first, and an English Language skills tracker.
A14: Resource mix | B14: For each subject and type of topic: how to split your time between flashcards, blurting, topic questions, past papers and writing practice – one mix for now → mocks and one for after mocks.
A15: Phases | B15: The five phases between now and your exams, with dates you can edit (your mock and exam dates).
A16: Weekly plan | B16: A week-by-week checklist from now to the end of exams with targets per week. Tick the "Done" column as you go.
A17: Subject plans | B17: For each subject: the papers, what full marks demands, the best resources and the traps to avoid, plus your weekly hours.
A18: Session template | B18: What to do in each 40-minute session, minute by minute, by session type.
A20: Assumptions | B20: Exam boards are taken from your flashcard decks (Edexcel IGCSE sciences, CS and English Literature; Edexcel GCSE History; OCR D&T; AQA German). English Language and Maths boards weren't given – assumed Edexcel IGCSE English Language A (4EA1) and Edexcel IGCSE Maths A (4MA1); change them on Subject plans if different. Exam dates are estimates for summer 2027 – replace them on Phases when the timetable is published. Weekly hours assume your timetable: 2 h Mon–Thu, 4 h Sat and Sun (16 h/week).

Sheet November tests
A1: November tests: Biology + English Language
A2: Year 9–10 content. Edit the yellow cells: test dates, which Biology topics are on the test, and your confidence (1–5) from the app's Strengths & weaknesses page.
A3: Biology test | B3: 46328 | C3: Assumed "very early November" – change to your real dates. | E3: Hours per week until the tests
A4: English Language test | B4: 46329 | E4: Biology | F4: 8 | G4: Plus daily flashcards for every subject (keeps your January material ticking over).
A5: Days to Biology test | B5: =B3-TODAY() -> 19 | E5: English Language | F5: 5
E6: Everything else (light, for January) | F6: 3
E7: Total | F7: =SUM(F4:F6) -> 16
A9: Biology topic tracker (Edexcel IGCSE 4BI1 topics in your app deck)
A10: Topic | B10: On the test? (Yes/No) | C10: Confidence 1–5 | D10: Priority (higher = revise first) | E10: Last blurt % | F10: Topic questions done | G10: Notes
A11: 1 Variety of living organisms | B11: Yes | C11: 3 | D11: =IF(B11="Yes",6-C11,0) -> 3
A12: 2a–b Cells and organisation | B12: Yes | C12: 3 | D12: =IF(B12="Yes",6-C12,0) -> 3
A13: 2c Biological molecules (incl. enzymes, food tests) | B13: Yes | C13: 3 | D13: =IF(B13="Yes",6-C13,0) -> 3
A14: 2d Movement of substances (diffusion, osmosis, active transport) | B14: Yes | C14: 3 | D14: =IF(B14="Yes",6-C14,0) -> 3
A15: 2e Human nutrition | B15: Yes | C15: 3 | D15: =IF(B15="Yes",6-C15,0) -> 3
A16: 2e Plant nutrition (photosynthesis) | B16: Yes | C16: 3 | D16: =IF(B16="Yes",6-C16,0) -> 3
A17: 2f Respiration | B17: Yes | C17: 3 | D17: =IF(B17="Yes",6-C17,0) -> 3
A18: 2g Gas exchange | B18: Yes | C18: 3 | D18: =IF(B18="Yes",6-C18,0) -> 3
A19: 2h Transport | B19: Yes | C19: 3 | D19: =IF(B19="Yes",6-C19,0) -> 3
A20: 2i Excretion | B20: No | C20: 3 | D20: =IF(B20="Yes",6-C20,0) -> 0
A21: 2j Coordination and response | B21: No | C21: 3 | D21: =IF(B21="Yes",6-C21,0) -> 0
A22: 3a Reproduction | B22: No | C22: 3 | D22: =IF(B22="Yes",6-C22,0) -> 0
... A25: 5 Use of biological resources | B25: No | C25: 3 | D25: =IF(B25="Yes",6-C25,0) -> 0
A26: Topics on the test | B26: =COUNTIF(B11:B25,"Yes") -> 9
A27: Which Year 9–10 topics are tested is a guess (topics 1–2h) – set "On the test?" to match what your teacher said. Orange rows = revise first. In the app, study just these topics with Flashcards → Browse/Custom study (search e.g. deck:"Biology::2h*"), and blurt each one in Tools → Blurting.
A29: English Language skills tracker (assumed Edexcel IGCSE English Language A, 4EA1)
A30: Skill | B30: How to practise | C30: Pieces done | D30: Last mark | E30: Out of | F30: % | G30: What to fix
A31: Retrieving information (short questions) | B31: Quick questions on an unseen extract – 1 mark per point, quote briefly | E31: 12 | F31: =IF(OR(D31="",E31=""),"",D31/E31)
A32: Language analysis | B32: Pick 3 quotations, name the technique, explain the effect on the reader (zoom in on single words) | E32: 12 | F32: =IF(OR(D32="",E32=""),"",D32/E32)
A33: Structure analysis | B33: Opening, shifts in focus, pace, ending – why the writer orders it this way | E33: 12 | F33: =IF(OR(D33="",E33=""),"",D33/E33)
A34: Comparing two texts | B34: Compare ideas and methods throughout with connectives (whereas, similarly) | E34: 22 | F34: =IF(OR(D34="",E34=""),"",D34/E34)
A35: Transactional writing (article, letter, speech) | B35: Plan 5 min, write 40 min: audience, purpose, form; rhetorical devices; check SPaG | E35: 45 | F35: =IF(OR(D35="",E35=""),"",D35/E35)
A36: Imaginative writing (story/description) | B36: Plan a clear structure; show-don't-tell; varied sentences; ambitious vocabulary; check SPaG | E36: 30 | F36: =IF(OR(D36="",E36=""),"",D36/E36)
A37: Marks out of are a guide for full-length questions – change them to match your test. Mark each piece with the mark scheme or the app's Tools → Mark my answer (English Language question types are built in).
A39: Day-by-day plan until the tests (follows your timetable: 2 h Mon–Thu, Fri off, 4 h Sat–Sun)
A40: Date | B40: Days to Biology test | C40: Session 1 (40 min) | D40: Session 2 (40 min) | E40: Session 3 (40 min) | F40: Weekend extra sessions | G40: Done?
A41: 46309 | B41: =IF($B$3-A41<0,"",$B$3-A41) -> 19 | C41: Flashcards: all due cards (Biology first); then Biology: blurt the top-priority topic (Tools → Blurting) → learn the gaps → 5 topic questions | D41: Biology: timed topic question set (SME/PMT) on the next-priority topic; mark; mistakes → cards | E41: English Language: structure + comparison practice on two short extracts | G41: No
A42: 46310 | B42: =IF($B$3-A42<0,"",$B$3-A42) -> 18 | C42: Flashcards: all due cards (Biology first); then Biology: blurt the top-priority topic (Tools → Blurting) → learn the gaps → 5 topic questions | D42: English Language: one extract – language analysis answer (timed); mark with "Mark my answer" | E42: Biology: timed topic question set (SME/PMT) on the next-priority topic; mark; mistakes → cards | G42: No
A43: 46311 | B43: =IF($B$3-A43<0,"",$B$3-A43) -> 17 | C43: Flashcards: all due cards (Biology first) + all other subjects | D43: Optional: Biology – one blurt of a weak topic | G43: No
A44: 46312 | B44: =IF($B$3-A44<0,"",$B$3-A44) -> 16 | C44: Flashcards: all due cards (Biology first); then Biology: blurt the top-priority topic (Tools → Blurting) → learn the gaps → 5 topic questions | D44: Biology: timed topic question set (SME/PMT) on the next-priority topic; mark; mistakes → cards | E44: English Language: one writing piece (plan 5 + write 35); mark; note SPaG fixes | F44: Session 4: Biology: blurt the top-priority topic (Tools → Blurting) → learn the gaps → 5 topic questions · Session 5: English Language: one extract – language analysis answer (timed); mark with "Mark my answer" · Session 6: January mocks – one session for English Lit or History (quotes/flashcards + blurt) | G44: No
A45: 46313 | B45: =IF($B$3-A45<0,"",$B$3-A45) -> 15 | C45: Flashcards: all due cards (Biology first); then Biology: timed topic question set (SME/PMT) on the next-priority topic; mark; mistakes → cards | D45: Biology: blurt the top-priority topic (Tools → Blurting) → learn the gaps → 5 topic questions | E45: English Language: one extract – language analysis answer (timed); mark with "Mark my answer" | F45: Session 4: Biology: blurt the top-priority topic (Tools → Blurting) → learn the gaps → 5 topic questions · Session 5: English Language: structure + comparison practice on two short extracts · Session 6: January mocks – one session for English Lit or History (quotes/flashcards + blurt) | G45: No
...

Sheet Phases
A1: Phases from now to the exams
A2: Edit the yellow dates (mocks, Easter, first and last exam). Weeks are calculated.
A4: Phase | B4: Starts | C4: Ends | D4: Weeks | E4: Main goal | F4: Flashcards | G4: Time split (learn & recall / questions / papers & essays / mistakes) | H4: Finish the phase able to…
A5: 0 November tests | B5: 46309 | C5: 46330 | D5: =ROUNDUP((C5-B5+1)/7,0) -> 4 | E5: Biology (Year 9–10 topics) and English Language tests in early November – see the November tests sheet. | F5: All due cards daily (all subjects); Biology cards first | G5: Biology & English Language: 30% / 35% / 25% / 10% | H5: walk into both tests having blurted every tested Biology topic and done timed English Language practice.
A6: 1 Secure the content | B6: 46331 | C6: 46369 | D6: =ROUNDUP((C6-B6+1)/7,0) -> 6 | E6: Finish learning every topic once; turn all content into flashcards you can recall. | F6: All due cards daily + new cards topic by topic | G6: 50% / 30% / 10% / 10% | H6: blurt each topic at 70%+ and answer topic questions without notes.
A7: 2 Mocks: prep and sit them | B7: 46370 | C7: 46404 | D7: =ROUNDUP((C7-B7+1)/7,0) -> 5 | E7: Timed papers for every subject, then sit the January mocks (assumed w/c 4 Jan). | F7: All due cards daily | G7: 30% / 20% / 40% / 10% | H7: sit every mock paper in time with a plan for each question type.
A8: 3 Exam practice | B8: 46405 | C8: 46474 | D8: =ROUNDUP((C8-B8+1)/7,0) -> 10 | E8: Past papers by subject; fix weak topics found in the mocks. | F8: All due cards daily | G8: 25% / 25% / 35% / 15% | H8: score grade 8+ on recent past papers in every subject.
A9: 4 Easter intensive | B9: 46475 | C9: 46495 | D9: =ROUNDUP((C9-B9+1)/7,0) -> 3 | E9: Full papers under exam conditions; perfect exam technique. | F9: All due cards daily | G9: 15% / 15% / 55% / 15% | H9: get near-full marks on most papers; know every mark-scheme phrase.
A10: 5 Exam season | B10: 46496 | C10: 46556 | D10: =ROUNDUP((C10-B10+1)/7,0) -> 9 | E10: Final papers and light review, paper by paper in exam order. | F10: Due cards only (keep reviews going) | G10: 25% / 10% / 50% / 15% | H10: walk into each paper having done its last 2–3 past papers.
A12: Total weeks to the end of exams | D12: =SUM(D5:D10) -> 37
A13: Note | B13: Dates are estimates: November tests assumed Mon 2 / Tue 3 Nov, mocks w/c 4 Jan 2027, exams mid-May to mid-June 2027. Replace them with your real dates.

Sheet Resource mix
A1: How to split your time – by subject and type of topic
A2: Each block should add up to 100% (the Total column turns red if not). Edit the percentages to suit you.
D3: NOW → MOCKS (Phases 1–2) | J3: AFTER MOCKS → EXAMS (Phases 3–5)
A4: Subject | B4: Type of topic | C4: Examples | D4: Learn (notes / video) | E4: App flashcards | F4: Blurting | G4: Topic questions (SME / PMT) | H4: Past papers / essays | I4: Total now → mocks | J4: App flashcards | K4: Blurting | L4: Topic questions (SME / PMT) | M4: Past papers / essays | N4: Mistake review | O4: Total mocks → exams | P4: Best resources for this | Q4: How to hit full marks
A5: Biology | B5: Recall-heavy content | C5: Cells, transport, coordination, reproduction, ecology | D5: 0.15 | E5: 0.35 | F5: 0.2 | G5: 0.25 | H5: 0.05 | I5: =SUM(D5:H5) -> 1 | J5: 0.25 | K5: 0.15 | L5: 0.25 | M5: 0.25 | N5: 0.1 | O5: =SUM(J5:N5) -> 1 | P5: App flashcards; Save My Exams (SME) Edexcel IGCSE revision notes + topic questions; PMT Edexcel IGCSE Biology topic questions | Q5: Learn mark-scheme keywords exactly (e.g. "active site", "denatured"). Blurt each topic, then do its SME/PMT questions.
A6: Biology | B6: Required practicals & data | C6: Practicals, graphs, magnification, % change | D6: 0.1 | E6: 0.25 | F6: 0.1 | G6: 0.4 | H6: 0.15 | I6: =SUM(D6:H6) -> 1 | J6: 0.15 | K6: 0.05 | L6: 0.3 | M6: 0.4 | N6: 0.1 | O6: =SUM(J6:N6) -> 1 | P6: App practical cards; PMT practical questions; past papers | Q6: Every practical: method, variables, control, results, safety. Practise "describe a method" 6-markers.
A7: Biology | B7: Extended answers | C7: Explain/evaluate 4–6 mark questions | D7: 0.05 | E7: 0.2 | F7: 0.15 | G7: 0.3 | H7: 0.3 | I7: =SUM(D7:H7) -> 1 | J7: 0.1 | K7: 0.1 | L7: 0.2 | M7: 0.45 | N7: 0.15 | O7: =SUM(J7:N7) -> 1 | P7: Past papers + mark schemes; app "Mark my answer" | Q7: Write a point per mark; use examiner phrasing; check against mark scheme.
A8: Chemistry | B8: Recall-heavy content | C8: Bonding, periodic table, tests, organic | D8: 0.15 | E8: 0.35 | F8: 0.2 | G8: 0.25 | H8: 0.05 | I8: =SUM(D8:H8) -> 1 | J8: 0.25 | K8: 0.15 | L8: 0.25 | M8: 0.25 | N8: 0.1 | O8: =SUM(J8:N8) -> 1 | P8: App flashcards; SME Edexcel IGCSE Chemistry notes + topic questions; PMT topic questions | Q8: Know every test (ion/gas) word-perfect including the result colour.
A9: Chemistry | B9: Calculations | C9: Moles, concentration, yield, energetics | D9: 0.1 | E9: 0.15 | F9: 0 | G9: 0.6 | H9: 0.15 | I9: =SUM(D9:H9) -> 1 | J9: 0.1 | K9: 0 | L9: 0.4 | M9: 0.4 | N9: 0.1 | O9: =SUM(J9:N9) -> 1 | P9: PMT and SME calculation question sets; past papers | Q9: Do 10+ questions per calculation type until automatic; always show units and working.
A10: Chemistry | B10: Practicals & extended answers | C10: Salt preparation, rates, electrolysis explanations | D10: 0.05 | E10: 0.25 | F10: 0.15 | G10: 0.3 | H10: 0.25 | I10: =SUM(D10:H10) -> 1 | J10: 0.15 | K10: 0.1 | L10: 0.25 | M10: 0.4 | N10: 0.1 | O10: =SUM(J10:N10) -> 1 | P10: Past papers; app practical cards | Q10: Learn full methods step by step; explain using particles/collisions with key terms.
A11: Physics | B11: Concepts & recall | C11: Forces, waves, electricity, radioactivity, astrophysics | D11: 0.15 | E11: 0.3 | F11: 0.2 | G11: 0.3 | H11: 0.05 | I11: =SUM(D11:H11) -> 1 | J11: 0.2 | K11: 0.15 | L11: 0.3 | M11: 0.25 | N11: 0.1 | O11: =SUM(J11:N11) -> 1 | P11: App flashcards; SME Edexcel IGCSE Physics; PMT topic questions | Q11: Know definitions precisely (e.g. "the rate of change of velocity").
A12: Physics | B12: Equations & calculations | C12: All recall equations, unit conversions, graphs | D12: 0.1 | E12: 0.25 | F12: 0 | G12: 0.55 | H12: 0.1 | I12: =SUM(D12:H12) -> 1 | J12: 0.15 | K12: 0 | L12: 0.4 | M12: 0.35 | N12: 0.1 | O12: =SUM(J12:N12) -> 1 | P12: App equation cards; PMT/SME calculation questions; past papers | Q12: Recall every equation instantly (flashcards); show substitution → answer → unit.
A13: Physics | B13: Practicals & explain questions | C13: Required practicals, EM induction, 6-markers | D13: 0.05 | E13: 0.25 | F13: 0.15 | G13: 0.3 | H13: 0.25 | I13: =SUM(D13:H13) -> 1 | J13: 0.15 | K13: 0.1 | L13: 0.25 | M13: 0.4 | N13: 0.1 | O13: =SUM(J13:N13) -> 1 | P13: Past papers; your EM induction revision sheet cards | Q13: Practise 6-mark "describe how" answers with a clear sequence.
A14: History | B14: Knowledge (events, dates, people) | C14: Medicine, Elizabeth, Cold War, Weimar & Nazi Germany | D14: 0.15 | E14: 0.4 | F14: 0.25 | G14: 0.15 | H14: 0.05 | I14: =SUM(D14:H14) -> 1 | J14: 0.3 | K14: 0.2 | L14: 0.15 | M14: 0.25 | N14: 0.1 | O14: =SUM(J14:N14) -> 1 | P14: App flashcards; blurting per key topic; SME/Seneca notes; textbook | Q14: Blurt timelines; learn 2–3 specific examples per key topic to use as evidence.
A15: History | B15: Exam question types | C15: Describe, explain, how far, sources, interpretations | D15: 0.05 | E15: 0.15 | F15: 0.1 | G15: 0.3 | H15: 0.4 | I15: =SUM(D15:H15) -> 1 | J15: 0.1 | K15: 0.05 | L15: 0.2 | M15: 0.55 | N15: 0.1 | O15: =SUM(J15:N15) -> 1 | P15: Past papers + mark schemes; app "Mark my answer"; exam technique cards | Q15: Practise each question type with the mark-scheme structure; for 16-markers judge, don't just describe.
A16: English Literature | B16: Quotes & context | C16: Macbeth, An Inspector Calls, Of Mice and Men | D16: 0.1 | E16: 0.3 | F16: 0.2 | G16: 0 | H16: 0.4 | I16: =SUM(D16:H16) -> 1 | J16: 0.25 | K16: 0.15 | L16: 0 | M16: 0.45 | N16: 0.15 | O16: =SUM(J16:N16) -> 1 | P16: App Quote learner + point → quote cards; Mr Bruff / Mr Salles videos for analysis ideas | Q16: Learn ~20 short quotes per text that each fit several themes; know context to link (AO4).
... A29: Design & Technology | B29: Maths & extended questions | C29: Calculations, design evaluations | D29: 0.05 | E29: 0.15 | F29: 0.1 | G29: 0.4 | H29: 0.3 | I29: =SUM(D29:H29) -> 1 | J29: 0.1 | K29: 0.05 | L29: 0.3 | M29: 0.45 | N29: 0.1 | O29: =SUM(J29:N29) -> 1 | P29: OCR past papers + mark schemes | Q29: Show working in calculations; evaluate with pros and cons and a conclusion.
A31: Key | B31: SME = Save My Exams · PMT = Physics & Maths Tutor (free topic questions and past papers) · "App" = this study app (flashcards, Quick Learn, Blurting, Quote learner, Past papers, Mark my answer).

Sheet Subject plans
A1: Subject plans and weekly hours
A2: Yellow = edit. Hours split your weekly total by priority weight.
A3: Weekly study hours | B3: 16 | C3: Daily flashcards (every subject, ~25–40 min/day) are on top of this and not counted here.
A5: Subject | B5: Board / papers | C5: Priority | D5: Weight | E5: Hours / week | F5: What full marks demands | G5: Best resources | H5: Common traps | I5: Mock target | J5: Final target
A6: English Literature | B6: Edexcel IGCSE 4ET1: Paper 1 poetry & modern prose; Paper 2 modern drama & literary heritage | C6: High | D6: 3 | E6: =$B$3*D6/SUM($D$6:$D$15) -> 2.2325581 | F6: Precise short quotes, analysis of methods, integrated context, comparison for poetry, timed essays | G6: App quotes & poem guide; past papers; Mr Bruff / Mr Salles; "Mark my answer" | H6: Retelling the plot; bolted-on context; long quotes; running out of time | I6: 7 | J6: 9
A7: Biology | B7: Edexcel IGCSE 4BI1: Paper 1 + Paper 2 (separate science) | C7: High | D7: 3 | E7: =$B$3*D7/SUM($D$6:$D$15) -> 2.2325581 | F7: Exact keyword definitions, all practicals, data and calculation questions | G7: App flashcards; SME notes + topic questions; PMT; past papers | H7: Vague wording ("it gets bigger"); forgetting units; skipping Paper 2 topics | I7: 8 | J7: 9
A8: History | B8: Edexcel GCSE 1HI0: Medicine + Western Front; Elizabethan England + Cold War; Weimar & Nazi Germany | C8: High | D8: 3 | E8: =$B$3*D8/SUM($D$6:$D$15) -> 2.2325581 | F8: Specific evidence for every point, sustained judgement in 16-markers, source and interpretation skills | G8: App flashcards + blurting; past papers; textbook; "Mark my answer" | H8: Describing instead of explaining; no judgement; generic evidence | I8: 7 | J8: 9
A9: Physics | B9: Edexcel IGCSE 4PH1: Paper 1 + Paper 2 | C9: Medium | D9: 2 | E9: =$B$3*D9/SUM($D$6:$D$15) -> 1.4883721 | F9: Every equation and unit, practicals, clear multi-step explanations | G9: App flashcards; PMT/SME questions; past papers | H9: Not rearranging equations; missing unit conversions | I9: 8 | J9: 9
A10: Chemistry | B10: Edexcel IGCSE 4CH1: Paper 1 + Paper 2 | C10: Medium | D10: 2 | E10: =$B$3*D10/SUM($D$6:$D$15) -> 1.4883721 | F10: Calculations, every test result, practical methods, particle explanations | G10: App flashcards; PMT/SME questions; past papers | H10: Unbalanced equations; wrong state symbols; vague test colours | I10: 8 | J10: 9
A11: German | B11: AQA GCSE 8662: listening, speaking, reading, writing | C11: Medium | D11: 2 | E11: =$B$3*D11/SUM($D$6:$D$15) -> 1.4883721 | F11: Wide vocabulary, accurate grammar and word order, three tenses, confident speaking | G11: App German deck; AQA past papers; speaking practice aloud | H11: Wrong genders/word order; English word order in translation | I11: 7 | J11: 9
A12: Computer Science | B12: Edexcel IGCSE 4CP0: Paper 1 theory; Paper 2 programming | C12: Medium | D12: 2 | E12: =$B$3*D12/SUM($D$6:$D$15) -> 1.4883721 | F12: Precise theory, fast calculations, confident Python under time pressure | G12: App flashcards; SME/PMT questions; coding practice; past papers | H12: Not practising code; mis-tracing algorithms | I12: 8 | J12: 9
A13: English Language | B13: Assumed Edexcel IGCSE English Language A (4EA1) | C13: Low | D13: 1.5 | E13: =$B$3*D13/SUM($D$6:$D$15) -> 1.1162791 | F13: Analysis of language and structure, comparison, controlled accurate writing | G13: Past papers; model answers; "Mark my answer" | H13: Feature-spotting without effect; weak SPaG | I13: 7 | J13: 8+
A14: Maths | B14: Assumed Edexcel IGCSE Maths A (4MA1, Higher) | C14: Low | D14: 1.5 | E14: =$B$3*D14/SUM($D$6:$D$15) -> 1.1162791 | F14: Accuracy across every topic, full working, fluency on harder questions | G14: Corbettmaths 5-a-day; Maths Genie; PMT; past papers | H14: Careless errors; not showing working; rusty topics | I14: 8 | J14: 9
A15: Design & Technology | B15: OCR GCSE J310 (exam 50% + NEA 50%) | C15: Low | D15: 1.5 | E15: =$B$3*D15/SUM($D$6:$D$15) -> 1.1162791 | F15: Specific materials and processes, maths questions, evaluative answers; strong NEA | G15: App flashcards; OCR past papers; NEA guidance | H15: Generic answers ("it is strong"); leaving NEA late | I15: 7 | J15: 9
A16: Total | E16: =SUM(E6:E15) -> 16
A18: Weights: High 3, Medium 2, Low 1.5 (from your timetable emphasis). Change a weight to rebalance the hours.

Sheet Weekly plan
A1: Week-by-week plan
A2: Phase and dates update from the Phases sheet. Tick "Done" (Yes/No) each Sunday and note what to fix.
A4: Week | B4: Week starting | C4: Phase | D4: Focus this week | E4: Daily flashcards | F4: Blurts | G4: Topic question sets | H4: Timed past papers / essays | I4: Done? | J4: Notes / what to fix next week
A5: 1 | B5: =Phases!B5-WEEKDAY(Phases!B5,3) -> 46307 | C5: =IFERROR(LOOKUP(B5,Phases!$B$5:$B$10,Phases!$A$5:$A$10),Phases!$A$5) -> 0 November tests | D5: November tests: Biology (tested Year 9–10 topics, weakest first) + English Language practice – see the November tests sheet; other subjects: due flashcards only | E5: All due | F5: 5 | G5: 4 | H5: 2 | I5: No
A6: 2 | B6: =B5+7 -> 46314 | C6: =IFERROR(LOOKUP(B6,Phases!$B$5:$B$10,Phases!$A$5:$A$10),Phases!$A$5) -> 0 November tests | D6: November tests: Biology (tested Year 9–10 topics, weakest first) + English Language practice – see the November tests sheet; other subjects: due flashcards only | E6: All due | F6: 5 | G6: 4 | H6: 2 | I6: No
A7: 3 | B7: =B6+7 -> 46321 | C7: =IFERROR(LOOKUP(B7,Phases!$B$5:$B$10,Phases!$A$5:$A$10),Phases!$A$5) -> 0 November tests | D7: November tests: Biology (tested Year 9–10 topics, weakest first) + English Language practice – see the November tests sheet; other subjects: due flashcards only | E7: All due | F7: 5 | G7: 4 | H7: 2 | I7: No
A8: 4 | B8: =B7+7 -> 46328 | C8: =IFERROR(LOOKUP(B8,Phases!$B$5:$B$10,Phases!$A$5:$A$10),Phases!$A$5) -> 0 November tests | D8: Finish learning 1–2 topics per subject; make/learn their cards; blurt each topic; topic questions | E8: All due | F8: 4 | G8: 6 | H8: 1 | I8: No
A9: 5 | B9: =B8+7 -> 46335 | C9: =IFERROR(LOOKUP(B9,Phases!$B$5:$B$10,Phases!$A$5:$A$10),Phases!$A$5) -> 1 Secure the content | D9: Finish learning 1–2 topics per subject; make/learn their cards; blurt each topic; topic questions | E9: All due | F9: 4 | G9: 6 | H9: 1 | I9: No
A10: 6 | B10: =B9+7 -> 46342 | C10: =IFERROR(LOOKUP(B10,Phases!$B$5:$B$10,Phases!$A$5:$A$10),Phases!$A$5) -> 1 Secure the content | D10: Finish learning 1–2 topics per subject; make/learn their cards; blurt each topic; topic questions | E10: All due | F10: 4 | G10: 6 | H10: 1 | I10: No
A11: 7 | B11: =B10+7 -> 46349 | C11: =IFERROR(LOOKUP(B11,Phases!$B$5:$B$10,Phases!$A$5:$A$10),Phases!$A$5) -> 1 Secure the content | D11: Finish learning 1–2 topics per subject; make/learn their cards; blurt each topic; topic questions | E11: All due | F11: 4 | G11: 6 | H11: 1 | I11: No
A12: 8 | B12: =B11+7 -> 46356 | C12: =IFERROR(LOOKUP(B12,Phases!$B$5:$B$10,Phases!$A$5:$A$10),Phases!$A$5) -> 1 Secure the content | D12: Finish learning 1–2 topics per subject; make/learn their cards; blurt each topic; topic questions | E12: All due | F12: 4 | G12: 6 | H12: 1 | I12: No
A13: 9 | B13: =B12+7 -> 46363 | C13: =IFERROR(LOOKUP(B13,Phases!$B$5:$B$10,Phases!$A$5:$A$10),Phases!$A$5) -> 1 Secure the content | D13: Finish learning 1–2 topics per subject; make/learn their cards; blurt each topic; topic questions | E13: All due | F13: 4 | G13: 6 | H13: 1 | I13: No
A14: 10 | B14: =B13+7 -> 46370 | C14: =IFERROR(LOOKUP(B14,Phases!$B$5:$B$10,Phases!$A$5:$A$10),Phases!$A$5) -> 2 Mocks: prep and sit them | D14: Mocks: timed paper per subject before Christmas, light flashcards on Christmas Day, sit the mocks w/c 4 Jan, log every lost mark | E14: All due | F14: 3 | G14: 3 | H14: 5 | I14: No
A15: 11 | B15: =B14+7 -> 46377 | C15: =IFERROR(LOOKUP(B15,Phases!$B$5:$B$10,Phases!$A$5:$A$10),Phases!$A$5) -> 2 Mocks: prep and sit them | D15: Mocks: timed paper per subject before Christmas, light flashcards on Christmas Day, sit the mocks w/c 4 Jan, log every lost mark | E15: All due | F15: 3 | G15: 3 | H15: 5 | I15: No
A16: 12 | B16: =B15+7 -> 46384 | C16: =IFERROR(LOOKUP(B16,Phases!$B$5:$B$10,Phases!$A$5:$A$10),Phases!$A$5) -> 2 Mocks: prep and sit them | D16: Mocks: timed paper per subject before Christmas, light flashcards on Christmas Day, sit the mocks w/c 4 Jan, log every lost mark | E16: All due | F16: 3 | G16: 3 | H16: 5 | I16: No
A17: 13 | B17: =B16+7 -> 46391 | C17: =IFERROR(LOOKUP(B17,Phases!$B$5:$B$10,Phases!$A$5:$A$10),Phases!$A$5) -> 2 Mocks: prep and sit them | D17: Mocks: timed paper per subject before Christmas, light flashcards on Christmas Day, sit the mocks w/c 4 Jan, log every lost mark | E17: All due | F17: 3 | G17: 3 | H17: 5 | I17: No
... A40: 36 | B40: =B39+7 -> 46552 | C40: =IFERROR(LOOKUP(B40,Phases!$B$5:$B$10,Phases!$A$5:$A$10),Phases!$A$5) -> 5 Exam season | D40: Exam season: last 2–3 papers for each upcoming exam; light flashcards; sleep well | E40: Due only | F40: 1 | G40: 1 | H40: 6 | I40: No
A42: Weeks done | C42: =COUNTIF(I5:I40,"Yes")&" of "&COUNTA(A5:A40) -> 0 of 36
A43: Totals planned | F43: =SUM(F5:F40) -> 86 | G43: =SUM(G5:G40) -> 118 | H43: =SUM(H5:H40) -> 181

Sheet Session template
A1: What to do in a 40-minute session
A2: Pick the session type that matches the timetable goal. Start every day with your due flashcards.
A4: Session type | B4: Minutes 0–5 | C4: Minutes 5–30 | D4: Minutes 30–40 | E4: Use when
A5: Learn a new topic | B5: Due flashcards for this subject | C5: Read SME notes / watch one video, then close it and blurt; check and fill gaps; add or unsuspend the topic's cards | D5: Do 3–5 short topic questions without notes | E5: Phase 1, first time through a topic
A6: Recall & strengthen | B6: Blurt the topic from memory (timer) | C6: App Blurting check → learn the gaps (Quick Learn set it makes); topic questions | D6: Mark, log mistakes, turn them into cards | E6: Topics rated 1–3 on Strengths & weaknesses
A7: Question practice | B7: Skim the mark scheme style for this topic | C7: One SME/PMT topic question set, timed (about 1 mark per minute) | D7: Mark strictly; every lost mark → mistakes log → flashcard | E7: All phases; calculations and practicals
A8: Timed paper / essay | B8: — | C8: Full paper or one essay in exam time (over two sessions if needed) | D8: Mark with the official mark scheme (or "Mark my answer" for essays); log mistakes | E8: Phases 2–5
A9: Quotes & English | B9: Quote learner – 10 quotes | C9: Plan 2 essays in 10 min each, or write one timed section | D9: Compare your plan with the point → quote cards; mark with "Mark my answer" | E9: English Literature (and Language writing)
A10: Languages | B10: German flashcards (both ways) | C10: Translation into German or a reading/listening paper section | D10: Speak 3 prepared answers aloud for the photo card / conversation | E10: German, every week
A13: Daily routine
A14: • | B14: Every day (including Fri and holidays): app flashcards – clear all due cards (25–40 min). Little and often keeps retention near 90%.
A15: • | B15: Each timetable session: follow the type above and the goals set on the session in the app's Timetable.
A16: • | B16: Every Sunday: check Strengths & weaknesses, pick next week's weakest topics, tick the Weekly plan, reschedule missed sessions in the app.
A17: • | B17: Every fortnight: one full past paper per subject (from Phase 2), logged in Past papers to track your predicted grade.
